[2024-12-06T18:37:48.241+0000] {local_task_job_runner.py:123} INFO - ::group::Pre task execution logs
[2024-12-06T18:37:48.264+0000] {taskinstance.py:2613} INFO - Dependencies all met for dep_context=non-requeueable deps ti=<TaskInstance: pyspark_etl_dag.run_pyspark_etl manual__2024-12-06T18:37:47.068773+00:00 [queued]>
[2024-12-06T18:37:48.271+0000] {taskinstance.py:2613} INFO - Dependencies all met for dep_context=requeueable deps ti=<TaskInstance: pyspark_etl_dag.run_pyspark_etl manual__2024-12-06T18:37:47.068773+00:00 [queued]>
[2024-12-06T18:37:48.272+0000] {taskinstance.py:2866} INFO - Starting attempt 1 of 1
[2024-12-06T18:37:48.282+0000] {taskinstance.py:2889} INFO - Executing <Task(SparkSubmitOperator): run_pyspark_etl> on 2024-12-06 18:37:47.068773+00:00
[2024-12-06T18:37:48.287+0000] {standard_task_runner.py:72} INFO - Started process 320 to run task
[2024-12-06T18:37:48.290+0000] {standard_task_runner.py:104} INFO - Running: ['***', 'tasks', 'run', 'pyspark_etl_dag', 'run_pyspark_etl', 'manual__2024-12-06T18:37:47.068773+00:00', '--job-id', '50', '--raw', '--subdir', 'DAGS_FOLDER/scripts_etl_dags.py', '--cfg-path', '/tmp/tmpb24dcwme']
[2024-12-06T18:37:48.293+0000] {standard_task_runner.py:105} INFO - Job 50: Subtask run_pyspark_etl
[2024-12-06T18:37:48.316+0000] {logging_mixin.py:190} WARNING - /home/***/.local/lib/python3.9/site-packages/***/settings.py:209 DeprecationWarning: The sql_alchemy_conn option in [core] has been moved to the sql_alchemy_conn option in [database] - the old setting has been used, but please update your config.
[2024-12-06T18:37:48.363+0000] {task_command.py:467} INFO - Running <TaskInstance: pyspark_etl_dag.run_pyspark_etl manual__2024-12-06T18:37:47.068773+00:00 [running]> on host 9a0780602dc6
[2024-12-06T18:37:48.457+0000] {taskinstance.py:3132} INFO - Exporting env vars: AIRFLOW_CTX_DAG_OWNER='***' AIRFLOW_CTX_DAG_ID='pyspark_etl_dag' AIRFLOW_CTX_TASK_ID='run_pyspark_etl' AIRFLOW_CTX_EXECUTION_DATE='2024-12-06T18:37:47.068773+00:00' AIRFLOW_CTX_TRY_NUMBER='1' AIRFLOW_CTX_DAG_RUN_ID='manual__2024-12-06T18:37:47.068773+00:00'
[2024-12-06T18:37:48.459+0000] {taskinstance.py:731} INFO - ::endgroup::
[2024-12-06T18:37:48.492+0000] {base.py:84} INFO - Retrieving connection 'spark_default'
[2024-12-06T18:37:48.493+0000] {spark_submit.py:473} INFO - Spark-Submit cmd: spark-submit --master yarn --conf spark.executor.memory=2g --conf spark.driver.memory=2g --name arrow-spark --queue root.default /opt/***/scripts/scripts_etl.py
[2024-12-06T18:37:51.153+0000] {spark_submit.py:634} INFO - 24/12/06 18:37:51 INFO SparkContext: Running Spark version 3.4.4
[2024-12-06T18:37:51.203+0000] {spark_submit.py:634} INFO - 24/12/06 18:37:51 WARN NativeCodeLoader: Unable to load native-hadoop library for your platform... using builtin-java classes where applicable
[2024-12-06T18:37:51.268+0000] {spark_submit.py:634} INFO - 24/12/06 18:37:51 INFO ResourceUtils: ==============================================================
[2024-12-06T18:37:51.269+0000] {spark_submit.py:634} INFO - 24/12/06 18:37:51 INFO ResourceUtils: No custom resources configured for spark.driver.
[2024-12-06T18:37:51.270+0000] {spark_submit.py:634} INFO - 24/12/06 18:37:51 INFO ResourceUtils: ==============================================================
[2024-12-06T18:37:51.270+0000] {spark_submit.py:634} INFO - 24/12/06 18:37:51 INFO SparkContext: Submitted application: PostgreSQL Integration
[2024-12-06T18:37:51.285+0000] {spark_submit.py:634} INFO - 24/12/06 18:37:51 INFO ResourceProfile: Default ResourceProfile created, executor resources: Map(cores -> name: cores, amount: 1, script: , vendor: , memory -> name: memory, amount: 2048, script: , vendor: , offHeap -> name: offHeap, amount: 0, script: , vendor: ), task resources: Map(cpus -> name: cpus, amount: 1.0)
[2024-12-06T18:37:51.296+0000] {spark_submit.py:634} INFO - 24/12/06 18:37:51 INFO ResourceProfile: Limiting resource is cpus at 1 tasks per executor
[2024-12-06T18:37:51.298+0000] {spark_submit.py:634} INFO - 24/12/06 18:37:51 INFO ResourceProfileManager: Added ResourceProfile id: 0
[2024-12-06T18:37:51.336+0000] {spark_submit.py:634} INFO - 24/12/06 18:37:51 INFO SecurityManager: Changing view acls to: ***
[2024-12-06T18:37:51.337+0000] {spark_submit.py:634} INFO - 24/12/06 18:37:51 INFO SecurityManager: Changing modify acls to: ***
[2024-12-06T18:37:51.338+0000] {spark_submit.py:634} INFO - 24/12/06 18:37:51 INFO SecurityManager: Changing view acls groups to:
[2024-12-06T18:37:51.339+0000] {spark_submit.py:634} INFO - 24/12/06 18:37:51 INFO SecurityManager: Changing modify acls groups to:
[2024-12-06T18:37:51.340+0000] {spark_submit.py:634} INFO - 24/12/06 18:37:51 INFO SecurityManager: SecurityManager: authentication disabled; ui acls disabled; users with view permissions: ***; groups with view permissions: EMPTY; users with modify permissions: ***; groups with modify permissions: EMPTY
[2024-12-06T18:37:51.494+0000] {spark_submit.py:634} INFO - 24/12/06 18:37:51 INFO Utils: Successfully started service 'sparkDriver' on port 46309.
[2024-12-06T18:37:51.519+0000] {spark_submit.py:634} INFO - 24/12/06 18:37:51 INFO SparkEnv: Registering MapOutputTracker
[2024-12-06T18:37:51.551+0000] {spark_submit.py:634} INFO - 24/12/06 18:37:51 INFO SparkEnv: Registering BlockManagerMaster
[2024-12-06T18:37:51.569+0000] {spark_submit.py:634} INFO - 24/12/06 18:37:51 INFO BlockManagerMasterEndpoint: Using org.apache.spark.storage.DefaultTopologyMapper for getting topology information
[2024-12-06T18:37:51.570+0000] {spark_submit.py:634} INFO - 24/12/06 18:37:51 INFO BlockManagerMasterEndpoint: BlockManagerMasterEndpoint up
[2024-12-06T18:37:51.596+0000] {spark_submit.py:634} INFO - 24/12/06 18:37:51 INFO SparkEnv: Registering BlockManagerMasterHeartbeat
[2024-12-06T18:37:51.615+0000] {spark_submit.py:634} INFO - 24/12/06 18:37:51 INFO DiskBlockManager: Created local directory at /tmp/blockmgr-1302900b-e37a-4e95-8bd6-207efb44e39f
[2024-12-06T18:37:51.634+0000] {spark_submit.py:634} INFO - 24/12/06 18:37:51 INFO MemoryStore: MemoryStore started with capacity 1048.8 MiB
[2024-12-06T18:37:51.677+0000] {spark_submit.py:634} INFO - 24/12/06 18:37:51 INFO SparkEnv: Registering OutputCommitCoordinator
[2024-12-06T18:37:51.793+0000] {spark_submit.py:634} INFO - 24/12/06 18:37:51 INFO JettyUtils: Start Jetty 0.0.0.0:4040 for SparkUI
[2024-12-06T18:37:51.839+0000] {spark_submit.py:634} INFO - 24/12/06 18:37:51 WARN Utils: Service 'SparkUI' could not bind on port 4040. Attempting port 4041.
[2024-12-06T18:37:51.847+0000] {spark_submit.py:634} INFO - 24/12/06 18:37:51 INFO Utils: Successfully started service 'SparkUI' on port 4041.
[2024-12-06T18:37:51.875+0000] {spark_submit.py:634} INFO - 24/12/06 18:37:51 INFO SparkContext: Added JAR /opt/***/scripts/postgresql-42.7.4.jar at spark://9a0780602dc6:46309/jars/postgresql-42.7.4.jar with timestamp 1733510271143
[2024-12-06T18:37:51.996+0000] {spark_submit.py:634} INFO - 24/12/06 18:37:51 INFO DefaultNoHARMFailoverProxyProvider: Connecting to ResourceManager at /0.0.0.0:8032
[2024-12-06T18:37:53.109+0000] {spark_submit.py:634} INFO - 24/12/06 18:37:53 INFO Client: Retrying connect to server: 0.0.0.0/0.0.0.0:8032. Already tried 0 time(s); retry policy is RetryUpToMaximumCountWithFixedSleep(maxRetries=10, sleepTime=1000 MILLISECONDS)
[2024-12-06T18:37:54.111+0000] {spark_submit.py:634} INFO - 24/12/06 18:37:54 INFO Client: Retrying connect to server: 0.0.0.0/0.0.0.0:8032. Already tried 1 time(s); retry policy is RetryUpToMaximumCountWithFixedSleep(maxRetries=10, sleepTime=1000 MILLISECONDS)
[2024-12-06T18:37:55.113+0000] {spark_submit.py:634} INFO - 24/12/06 18:37:55 INFO Client: Retrying connect to server: 0.0.0.0/0.0.0.0:8032. Already tried 2 time(s); retry policy is RetryUpToMaximumCountWithFixedSleep(maxRetries=10, sleepTime=1000 MILLISECONDS)
[2024-12-06T18:37:56.115+0000] {spark_submit.py:634} INFO - 24/12/06 18:37:56 INFO Client: Retrying connect to server: 0.0.0.0/0.0.0.0:8032. Already tried 3 time(s); retry policy is RetryUpToMaximumCountWithFixedSleep(maxRetries=10, sleepTime=1000 MILLISECONDS)
[2024-12-06T18:37:57.118+0000] {spark_submit.py:634} INFO - 24/12/06 18:37:57 INFO Client: Retrying connect to server: 0.0.0.0/0.0.0.0:8032. Already tried 4 time(s); retry policy is RetryUpToMaximumCountWithFixedSleep(maxRetries=10, sleepTime=1000 MILLISECONDS)
[2024-12-06T18:37:58.121+0000] {spark_submit.py:634} INFO - 24/12/06 18:37:58 INFO Client: Retrying connect to server: 0.0.0.0/0.0.0.0:8032. Already tried 5 time(s); retry policy is RetryUpToMaximumCountWithFixedSleep(maxRetries=10, sleepTime=1000 MILLISECONDS)
[2024-12-06T18:37:59.123+0000] {spark_submit.py:634} INFO - 24/12/06 18:37:59 INFO Client: Retrying connect to server: 0.0.0.0/0.0.0.0:8032. Already tried 6 time(s); retry policy is RetryUpToMaximumCountWithFixedSleep(maxRetries=10, sleepTime=1000 MILLISECONDS)
[2024-12-06T18:38:00.124+0000] {spark_submit.py:634} INFO - 24/12/06 18:38:00 INFO Client: Retrying connect to server: 0.0.0.0/0.0.0.0:8032. Already tried 7 time(s); retry policy is RetryUpToMaximumCountWithFixedSleep(maxRetries=10, sleepTime=1000 MILLISECONDS)
[2024-12-06T18:38:01.127+0000] {spark_submit.py:634} INFO - 24/12/06 18:38:01 INFO Client: Retrying connect to server: 0.0.0.0/0.0.0.0:8032. Already tried 8 time(s); retry policy is RetryUpToMaximumCountWithFixedSleep(maxRetries=10, sleepTime=1000 MILLISECONDS)
[2024-12-06T18:38:02.129+0000] {spark_submit.py:634} INFO - 24/12/06 18:38:02 INFO Client: Retrying connect to server: 0.0.0.0/0.0.0.0:8032. Already tried 9 time(s); retry policy is RetryUpToMaximumCountWithFixedSleep(maxRetries=10, sleepTime=1000 MILLISECONDS)
[2024-12-06T18:38:03.139+0000] {spark_submit.py:634} INFO - 24/12/06 18:38:03 INFO Client: Retrying connect to server: 0.0.0.0/0.0.0.0:8032. Already tried 0 time(s); retry policy is RetryUpToMaximumCountWithFixedSleep(maxRetries=10, sleepTime=1000 MILLISECONDS)
[2024-12-06T18:38:04.140+0000] {spark_submit.py:634} INFO - 24/12/06 18:38:04 INFO Client: Retrying connect to server: 0.0.0.0/0.0.0.0:8032. Already tried 1 time(s); retry policy is RetryUpToMaximumCountWithFixedSleep(maxRetries=10, sleepTime=1000 MILLISECONDS)
[2024-12-06T18:38:05.142+0000] {spark_submit.py:634} INFO - 24/12/06 18:38:05 INFO Client: Retrying connect to server: 0.0.0.0/0.0.0.0:8032. Already tried 2 time(s); retry policy is RetryUpToMaximumCountWithFixedSleep(maxRetries=10, sleepTime=1000 MILLISECONDS)
[2024-12-06T18:38:06.145+0000] {spark_submit.py:634} INFO - 24/12/06 18:38:06 INFO Client: Retrying connect to server: 0.0.0.0/0.0.0.0:8032. Already tried 3 time(s); retry policy is RetryUpToMaximumCountWithFixedSleep(maxRetries=10, sleepTime=1000 MILLISECONDS)
[2024-12-06T18:38:07.147+0000] {spark_submit.py:634} INFO - 24/12/06 18:38:07 INFO Client: Retrying connect to server: 0.0.0.0/0.0.0.0:8032. Already tried 4 time(s); retry policy is RetryUpToMaximumCountWithFixedSleep(maxRetries=10, sleepTime=1000 MILLISECONDS)
[2024-12-06T18:38:08.149+0000] {spark_submit.py:634} INFO - 24/12/06 18:38:08 INFO Client: Retrying connect to server: 0.0.0.0/0.0.0.0:8032. Already tried 5 time(s); retry policy is RetryUpToMaximumCountWithFixedSleep(maxRetries=10, sleepTime=1000 MILLISECONDS)
[2024-12-06T18:38:09.151+0000] {spark_submit.py:634} INFO - 24/12/06 18:38:09 INFO Client: Retrying connect to server: 0.0.0.0/0.0.0.0:8032. Already tried 6 time(s); retry policy is RetryUpToMaximumCountWithFixedSleep(maxRetries=10, sleepTime=1000 MILLISECONDS)
[2024-12-06T18:38:10.153+0000] {spark_submit.py:634} INFO - 24/12/06 18:38:10 INFO Client: Retrying connect to server: 0.0.0.0/0.0.0.0:8032. Already tried 7 time(s); retry policy is RetryUpToMaximumCountWithFixedSleep(maxRetries=10, sleepTime=1000 MILLISECONDS)
[2024-12-06T18:38:11.154+0000] {spark_submit.py:634} INFO - 24/12/06 18:38:11 INFO Client: Retrying connect to server: 0.0.0.0/0.0.0.0:8032. Already tried 8 time(s); retry policy is RetryUpToMaximumCountWithFixedSleep(maxRetries=10, sleepTime=1000 MILLISECONDS)
[2024-12-06T18:38:12.155+0000] {spark_submit.py:634} INFO - 24/12/06 18:38:12 INFO Client: Retrying connect to server: 0.0.0.0/0.0.0.0:8032. Already tried 9 time(s); retry policy is RetryUpToMaximumCountWithFixedSleep(maxRetries=10, sleepTime=1000 MILLISECONDS)
[2024-12-06T18:38:12.156+0000] {spark_submit.py:634} INFO - 24/12/06 18:38:12 INFO RetryInvocationHandler: java.net.ConnectException: Your endpoint configuration is wrong; For more details see:  http://wiki.apache.org/hadoop/UnsetHostnameOrPort, while invoking ApplicationClientProtocolPBClientImpl.getNewApplication over null after 1 failover attempts. Trying to failover after sleeping for 24689ms.
[2024-12-06T18:38:37.844+0000] {spark_submit.py:634} INFO - 24/12/06 18:38:37 INFO Client: Retrying connect to server: 0.0.0.0/0.0.0.0:8032. Already tried 0 time(s); retry policy is RetryUpToMaximumCountWithFixedSleep(maxRetries=10, sleepTime=1000 MILLISECONDS)
[2024-12-06T18:38:38.845+0000] {spark_submit.py:634} INFO - 24/12/06 18:38:38 INFO Client: Retrying connect to server: 0.0.0.0/0.0.0.0:8032. Already tried 1 time(s); retry policy is RetryUpToMaximumCountWithFixedSleep(maxRetries=10, sleepTime=1000 MILLISECONDS)
[2024-12-06T18:38:39.846+0000] {spark_submit.py:634} INFO - 24/12/06 18:38:39 INFO Client: Retrying connect to server: 0.0.0.0/0.0.0.0:8032. Already tried 2 time(s); retry policy is RetryUpToMaximumCountWithFixedSleep(maxRetries=10, sleepTime=1000 MILLISECONDS)
[2024-12-06T18:38:40.847+0000] {spark_submit.py:634} INFO - 24/12/06 18:38:40 INFO Client: Retrying connect to server: 0.0.0.0/0.0.0.0:8032. Already tried 3 time(s); retry policy is RetryUpToMaximumCountWithFixedSleep(maxRetries=10, sleepTime=1000 MILLISECONDS)
[2024-12-06T18:38:41.849+0000] {spark_submit.py:634} INFO - 24/12/06 18:38:41 INFO Client: Retrying connect to server: 0.0.0.0/0.0.0.0:8032. Already tried 4 time(s); retry policy is RetryUpToMaximumCountWithFixedSleep(maxRetries=10, sleepTime=1000 MILLISECONDS)
[2024-12-06T18:38:42.849+0000] {spark_submit.py:634} INFO - 24/12/06 18:38:42 INFO Client: Retrying connect to server: 0.0.0.0/0.0.0.0:8032. Already tried 5 time(s); retry policy is RetryUpToMaximumCountWithFixedSleep(maxRetries=10, sleepTime=1000 MILLISECONDS)
[2024-12-06T18:38:43.850+0000] {spark_submit.py:634} INFO - 24/12/06 18:38:43 INFO Client: Retrying connect to server: 0.0.0.0/0.0.0.0:8032. Already tried 6 time(s); retry policy is RetryUpToMaximumCountWithFixedSleep(maxRetries=10, sleepTime=1000 MILLISECONDS)
[2024-12-06T18:38:44.850+0000] {spark_submit.py:634} INFO - 24/12/06 18:38:44 INFO Client: Retrying connect to server: 0.0.0.0/0.0.0.0:8032. Already tried 7 time(s); retry policy is RetryUpToMaximumCountWithFixedSleep(maxRetries=10, sleepTime=1000 MILLISECONDS)
[2024-12-06T18:38:45.851+0000] {spark_submit.py:634} INFO - 24/12/06 18:38:45 INFO Client: Retrying connect to server: 0.0.0.0/0.0.0.0:8032. Already tried 8 time(s); retry policy is RetryUpToMaximumCountWithFixedSleep(maxRetries=10, sleepTime=1000 MILLISECONDS)
[2024-12-06T18:38:46.853+0000] {spark_submit.py:634} INFO - 24/12/06 18:38:46 INFO Client: Retrying connect to server: 0.0.0.0/0.0.0.0:8032. Already tried 9 time(s); retry policy is RetryUpToMaximumCountWithFixedSleep(maxRetries=10, sleepTime=1000 MILLISECONDS)
[2024-12-06T18:38:46.857+0000] {spark_submit.py:634} INFO - 24/12/06 18:38:46 INFO RetryInvocationHandler: java.net.ConnectException: Your endpoint configuration is wrong; For more details see:  http://wiki.apache.org/hadoop/UnsetHostnameOrPort, while invoking ApplicationClientProtocolPBClientImpl.getNewApplication over null after 2 failover attempts. Trying to failover after sleeping for 23024ms.
[2024-12-06T18:39:10.884+0000] {spark_submit.py:634} INFO - 24/12/06 18:39:10 INFO Client: Retrying connect to server: 0.0.0.0/0.0.0.0:8032. Already tried 0 time(s); retry policy is RetryUpToMaximumCountWithFixedSleep(maxRetries=10, sleepTime=1000 MILLISECONDS)
[2024-12-06T18:39:11.886+0000] {spark_submit.py:634} INFO - 24/12/06 18:39:11 INFO Client: Retrying connect to server: 0.0.0.0/0.0.0.0:8032. Already tried 1 time(s); retry policy is RetryUpToMaximumCountWithFixedSleep(maxRetries=10, sleepTime=1000 MILLISECONDS)
[2024-12-06T18:39:12.888+0000] {spark_submit.py:634} INFO - 24/12/06 18:39:12 INFO Client: Retrying connect to server: 0.0.0.0/0.0.0.0:8032. Already tried 2 time(s); retry policy is RetryUpToMaximumCountWithFixedSleep(maxRetries=10, sleepTime=1000 MILLISECONDS)
[2024-12-06T18:39:13.889+0000] {spark_submit.py:634} INFO - 24/12/06 18:39:13 INFO Client: Retrying connect to server: 0.0.0.0/0.0.0.0:8032. Already tried 3 time(s); retry policy is RetryUpToMaximumCountWithFixedSleep(maxRetries=10, sleepTime=1000 MILLISECONDS)
[2024-12-06T18:39:14.890+0000] {spark_submit.py:634} INFO - 24/12/06 18:39:14 INFO Client: Retrying connect to server: 0.0.0.0/0.0.0.0:8032. Already tried 4 time(s); retry policy is RetryUpToMaximumCountWithFixedSleep(maxRetries=10, sleepTime=1000 MILLISECONDS)
[2024-12-06T18:39:15.892+0000] {spark_submit.py:634} INFO - 24/12/06 18:39:15 INFO Client: Retrying connect to server: 0.0.0.0/0.0.0.0:8032. Already tried 5 time(s); retry policy is RetryUpToMaximumCountWithFixedSleep(maxRetries=10, sleepTime=1000 MILLISECONDS)
[2024-12-06T18:39:16.894+0000] {spark_submit.py:634} INFO - 24/12/06 18:39:16 INFO Client: Retrying connect to server: 0.0.0.0/0.0.0.0:8032. Already tried 6 time(s); retry policy is RetryUpToMaximumCountWithFixedSleep(maxRetries=10, sleepTime=1000 MILLISECONDS)
[2024-12-06T18:39:17.896+0000] {spark_submit.py:634} INFO - 24/12/06 18:39:17 INFO Client: Retrying connect to server: 0.0.0.0/0.0.0.0:8032. Already tried 7 time(s); retry policy is RetryUpToMaximumCountWithFixedSleep(maxRetries=10, sleepTime=1000 MILLISECONDS)
[2024-12-06T18:39:18.898+0000] {spark_submit.py:634} INFO - 24/12/06 18:39:18 INFO Client: Retrying connect to server: 0.0.0.0/0.0.0.0:8032. Already tried 8 time(s); retry policy is RetryUpToMaximumCountWithFixedSleep(maxRetries=10, sleepTime=1000 MILLISECONDS)
[2024-12-06T18:39:19.901+0000] {spark_submit.py:634} INFO - 24/12/06 18:39:19 INFO Client: Retrying connect to server: 0.0.0.0/0.0.0.0:8032. Already tried 9 time(s); retry policy is RetryUpToMaximumCountWithFixedSleep(maxRetries=10, sleepTime=1000 MILLISECONDS)
[2024-12-06T18:39:19.905+0000] {spark_submit.py:634} INFO - 24/12/06 18:39:19 INFO RetryInvocationHandler: java.net.ConnectException: Your endpoint configuration is wrong; For more details see:  http://wiki.apache.org/hadoop/UnsetHostnameOrPort, while invoking ApplicationClientProtocolPBClientImpl.getNewApplication over null after 3 failover attempts. Trying to failover after sleeping for 15198ms.
[2024-12-06T18:39:36.102+0000] {spark_submit.py:634} INFO - 24/12/06 18:39:36 INFO Client: Retrying connect to server: 0.0.0.0/0.0.0.0:8032. Already tried 0 time(s); retry policy is RetryUpToMaximumCountWithFixedSleep(maxRetries=10, sleepTime=1000 MILLISECONDS)
[2024-12-06T18:39:37.102+0000] {spark_submit.py:634} INFO - 24/12/06 18:39:37 INFO Client: Retrying connect to server: 0.0.0.0/0.0.0.0:8032. Already tried 1 time(s); retry policy is RetryUpToMaximumCountWithFixedSleep(maxRetries=10, sleepTime=1000 MILLISECONDS)
[2024-12-06T18:39:38.103+0000] {spark_submit.py:634} INFO - 24/12/06 18:39:38 INFO Client: Retrying connect to server: 0.0.0.0/0.0.0.0:8032. Already tried 2 time(s); retry policy is RetryUpToMaximumCountWithFixedSleep(maxRetries=10, sleepTime=1000 MILLISECONDS)
[2024-12-06T18:39:39.104+0000] {spark_submit.py:634} INFO - 24/12/06 18:39:39 INFO Client: Retrying connect to server: 0.0.0.0/0.0.0.0:8032. Already tried 3 time(s); retry policy is RetryUpToMaximumCountWithFixedSleep(maxRetries=10, sleepTime=1000 MILLISECONDS)
[2024-12-06T18:39:39.511+0000] {local_task_job_runner.py:346} WARNING - State of this instance has been externally set to None. Terminating instance.
[2024-12-06T18:39:39.513+0000] {local_task_job_runner.py:245} INFO - ::endgroup::
[2024-12-06T18:39:39.515+0000] {process_utils.py:132} INFO - Sending 15 to group 320. PIDs of all processes in the group: [322, 367, 320]
[2024-12-06T18:39:39.516+0000] {process_utils.py:87} INFO - Sending the signal 15 to group 320
[2024-12-06T18:39:39.517+0000] {taskinstance.py:3093} ERROR - Received SIGTERM. Terminating subprocesses.
[2024-12-06T18:39:39.518+0000] {spark_submit.py:760} INFO - Sending kill signal to spark-submit
[2024-12-06T18:39:39.521+0000] {process_utils.py:80} INFO - Process psutil.Process(pid=367, status='terminated', started='18:37:49') (367) terminated with exit code None
[2024-12-06T18:39:39.539+0000] {taskinstance.py:3311} ERROR - Task failed with exception
Traceback (most recent call last):
  File "/home/airflow/.local/lib/python3.9/site-packages/airflow/models/taskinstance.py", line 767, in _execute_task
    result = _execute_callable(context=context, **execute_callable_kwargs)
  File "/home/airflow/.local/lib/python3.9/site-packages/airflow/models/taskinstance.py", line 733, in _execute_callable
    return ExecutionCallableRunner(
  File "/home/airflow/.local/lib/python3.9/site-packages/airflow/utils/operator_helpers.py", line 252, in run
    return self.func(*args, **kwargs)
  File "/home/airflow/.local/lib/python3.9/site-packages/airflow/models/baseoperator.py", line 417, in wrapper
    return func(self, *args, **kwargs)
  File "/home/airflow/.local/lib/python3.9/site-packages/airflow/providers/apache/spark/operators/spark_submit.py", line 176, in execute
    self._hook.submit(self.application)
  File "/home/airflow/.local/lib/python3.9/site-packages/airflow/providers/apache/spark/hooks/spark_submit.py", line 548, in submit
    self._process_spark_submit_log(iter(self._submit_sp.stdout))  # type: ignore
  File "/home/airflow/.local/lib/python3.9/site-packages/airflow/providers/apache/spark/hooks/spark_submit.py", line 597, in _process_spark_submit_log
    for line in itr:
  File "/home/airflow/.local/lib/python3.9/site-packages/airflow/models/taskinstance.py", line 3095, in signal_handler
    raise AirflowTaskTerminated("Task received SIGTERM signal")
airflow.exceptions.AirflowTaskTerminated: Task received SIGTERM signal
[2024-12-06T18:39:39.543+0000] {taskinstance.py:1225} INFO - Marking task as FAILED. dag_id=pyspark_etl_dag, task_id=run_pyspark_etl, run_id=manual__2024-12-06T18:37:47.068773+00:00, execution_date=20241206T183747, start_date=20241206T183748, end_date=20241206T183939
[2024-12-06T18:39:39.557+0000] {taskinstance.py:340} INFO - ::group::Post task execution logs
[2024-12-06T18:39:39.558+0000] {standard_task_runner.py:124} ERROR - Failed to execute job 50 for task run_pyspark_etl ((psycopg2.errors.ForeignKeyViolation) insert or update on table "task_fail" violates foreign key constraint "task_fail_ti_fkey"
DETAIL:  Key (dag_id, task_id, run_id, map_index)=(pyspark_etl_dag, run_pyspark_etl, manual__2024-12-06T18:37:47.068773+00:00, -1) is not present in table "task_instance".

[SQL: INSERT INTO task_fail (task_id, dag_id, run_id, map_index, start_date, end_date, duration) VALUES (%(task_id)s, %(dag_id)s, %(run_id)s, %(map_index)s, %(start_date)s, %(end_date)s, %(duration)s) RETURNING task_fail.id]
[parameters: {'task_id': 'run_pyspark_etl', 'dag_id': 'pyspark_etl_dag', 'run_id': 'manual__2024-12-06T18:37:47.068773+00:00', 'map_index': -1, 'start_date': datetime.datetime(2024, 12, 6, 18, 37, 48, 265469, tzinfo=Timezone('UTC')), 'end_date': datetime.datetime(2024, 12, 6, 18, 39, 39, 542601, tzinfo=Timezone('UTC')), 'duration': 111}]
(Background on this error at: https://sqlalche.me/e/14/gkpj); 320)
Traceback (most recent call last):
  File "/home/airflow/.local/lib/python3.9/site-packages/airflow/models/taskinstance.py", line 273, in _run_raw_task
    TaskInstance._execute_task_with_callbacks(
  File "/home/airflow/.local/lib/python3.9/site-packages/airflow/models/taskinstance.py", line 3159, in _execute_task_with_callbacks
    result = self._execute_task(context, task_orig)
  File "/home/airflow/.local/lib/python3.9/site-packages/airflow/models/taskinstance.py", line 3183, in _execute_task
    return _execute_task(self, context, task_orig)
  File "/home/airflow/.local/lib/python3.9/site-packages/airflow/models/taskinstance.py", line 767, in _execute_task
    result = _execute_callable(context=context, **execute_callable_kwargs)
  File "/home/airflow/.local/lib/python3.9/site-packages/airflow/models/taskinstance.py", line 733, in _execute_callable
    return ExecutionCallableRunner(
  File "/home/airflow/.local/lib/python3.9/site-packages/airflow/utils/operator_helpers.py", line 252, in run
    return self.func(*args, **kwargs)
  File "/home/airflow/.local/lib/python3.9/site-packages/airflow/models/baseoperator.py", line 417, in wrapper
    return func(self, *args, **kwargs)
  File "/home/airflow/.local/lib/python3.9/site-packages/airflow/providers/apache/spark/operators/spark_submit.py", line 176, in execute
    self._hook.submit(self.application)
  File "/home/airflow/.local/lib/python3.9/site-packages/airflow/providers/apache/spark/hooks/spark_submit.py", line 548, in submit
    self._process_spark_submit_log(iter(self._submit_sp.stdout))  # type: ignore
  File "/home/airflow/.local/lib/python3.9/site-packages/airflow/providers/apache/spark/hooks/spark_submit.py", line 597, in _process_spark_submit_log
    for line in itr:
  File "/home/airflow/.local/lib/python3.9/site-packages/airflow/models/taskinstance.py", line 3095, in signal_handler
    raise AirflowTaskTerminated("Task received SIGTERM signal")
airflow.exceptions.AirflowTaskTerminated: Task received SIGTERM signal

During handling of the above exception, another exception occurred:

Traceback (most recent call last):
  File "/home/airflow/.local/lib/python3.9/site-packages/sqlalchemy/engine/base.py", line 1900, in _execute_context
    self.dialect.do_execute(
  File "/home/airflow/.local/lib/python3.9/site-packages/sqlalchemy/engine/default.py", line 736, in do_execute
    cursor.execute(statement, parameters)
psycopg2.errors.ForeignKeyViolation: insert or update on table "task_fail" violates foreign key constraint "task_fail_ti_fkey"
DETAIL:  Key (dag_id, task_id, run_id, map_index)=(pyspark_etl_dag, run_pyspark_etl, manual__2024-12-06T18:37:47.068773+00:00, -1) is not present in table "task_instance".


The above exception was the direct cause of the following exception:

Traceback (most recent call last):
  File "/home/airflow/.local/lib/python3.9/site-packages/airflow/task/task_runner/standard_task_runner.py", line 117, in _start_by_fork
    ret = args.func(args, dag=self.dag)
  File "/home/airflow/.local/lib/python3.9/site-packages/airflow/cli/cli_config.py", line 49, in command
    return func(*args, **kwargs)
  File "/home/airflow/.local/lib/python3.9/site-packages/airflow/utils/cli.py", line 116, in wrapper
    return f(*args, **kwargs)
  File "/home/airflow/.local/lib/python3.9/site-packages/airflow/cli/commands/task_command.py", line 483, in task_run
    task_return_code = _run_task_by_selected_method(args, _dag, ti)
  File "/home/airflow/.local/lib/python3.9/site-packages/airflow/cli/commands/task_command.py", line 256, in _run_task_by_selected_method
    return _run_raw_task(args, ti)
  File "/home/airflow/.local/lib/python3.9/site-packages/airflow/cli/commands/task_command.py", line 341, in _run_raw_task
    return ti._run_raw_task(
  File "/home/airflow/.local/lib/python3.9/site-packages/airflow/utils/session.py", line 97, in wrapper
    return func(*args, session=session, **kwargs)
  File "/home/airflow/.local/lib/python3.9/site-packages/airflow/models/taskinstance.py", line 3005, in _run_raw_task
    return _run_raw_task(
  File "/home/airflow/.local/lib/python3.9/site-packages/airflow/models/taskinstance.py", line 327, in _run_raw_task
    ti.handle_failure(e, test_mode, context, session=session)
  File "/home/airflow/.local/lib/python3.9/site-packages/airflow/utils/session.py", line 94, in wrapper
    return func(*args, **kwargs)
  File "/home/airflow/.local/lib/python3.9/site-packages/airflow/models/taskinstance.py", line 3428, in handle_failure
    _handle_failure(
  File "/home/airflow/.local/lib/python3.9/site-packages/airflow/utils/session.py", line 94, in wrapper
    return func(*args, **kwargs)
  File "/home/airflow/.local/lib/python3.9/site-packages/airflow/api_internal/internal_api_call.py", line 166, in wrapper
    return func(*args, **kwargs)
  File "/home/airflow/.local/lib/python3.9/site-packages/airflow/models/taskinstance.py", line 1243, in _handle_failure
    TaskInstance.save_to_db(failure_context["ti"], session)
  File "/home/airflow/.local/lib/python3.9/site-packages/airflow/api_internal/internal_api_call.py", line 166, in wrapper
    return func(*args, **kwargs)
  File "/home/airflow/.local/lib/python3.9/site-packages/airflow/utils/session.py", line 94, in wrapper
    return func(*args, **kwargs)
  File "/home/airflow/.local/lib/python3.9/site-packages/airflow/models/taskinstance.py", line 3400, in save_to_db
    session.flush()
  File "/home/airflow/.local/lib/python3.9/site-packages/sqlalchemy/orm/session.py", line 3444, in flush
    self._flush(objects)
  File "/home/airflow/.local/lib/python3.9/site-packages/sqlalchemy/orm/session.py", line 3584, in _flush
    transaction.rollback(_capture_exception=True)
  File "/home/airflow/.local/lib/python3.9/site-packages/sqlalchemy/util/langhelpers.py", line 70, in __exit__
    compat.raise_(
  File "/home/airflow/.local/lib/python3.9/site-packages/sqlalchemy/util/compat.py", line 210, in raise_
    raise exception
  File "/home/airflow/.local/lib/python3.9/site-packages/sqlalchemy/orm/session.py", line 3544, in _flush
    flush_context.execute()
  File "/home/airflow/.local/lib/python3.9/site-packages/sqlalchemy/orm/unitofwork.py", line 456, in execute
    rec.execute(self)
  File "/home/airflow/.local/lib/python3.9/site-packages/sqlalchemy/orm/unitofwork.py", line 630, in execute
    util.preloaded.orm_persistence.save_obj(
  File "/home/airflow/.local/lib/python3.9/site-packages/sqlalchemy/orm/persistence.py", line 245, in save_obj
    _emit_insert_statements(
  File "/home/airflow/.local/lib/python3.9/site-packages/sqlalchemy/orm/persistence.py", line 1238, in _emit_insert_statements
    result = connection._execute_20(
  File "/home/airflow/.local/lib/python3.9/site-packages/sqlalchemy/engine/base.py", line 1705, in _execute_20
    return meth(self, args_10style, kwargs_10style, execution_options)
  File "/home/airflow/.local/lib/python3.9/site-packages/sqlalchemy/sql/elements.py", line 334, in _execute_on_connection
    return connection._execute_clauseelement(
  File "/home/airflow/.local/lib/python3.9/site-packages/sqlalchemy/engine/base.py", line 1572, in _execute_clauseelement
    ret = self._execute_context(
  File "/home/airflow/.local/lib/python3.9/site-packages/sqlalchemy/engine/base.py", line 1943, in _execute_context
    self._handle_dbapi_exception(
  File "/home/airflow/.local/lib/python3.9/site-packages/sqlalchemy/engine/base.py", line 2124, in _handle_dbapi_exception
    util.raise_(
  File "/home/airflow/.local/lib/python3.9/site-packages/sqlalchemy/util/compat.py", line 210, in raise_
    raise exception
  File "/home/airflow/.local/lib/python3.9/site-packages/sqlalchemy/engine/base.py", line 1900, in _execute_context
    self.dialect.do_execute(
  File "/home/airflow/.local/lib/python3.9/site-packages/sqlalchemy/engine/default.py", line 736, in do_execute
    cursor.execute(statement, parameters)
sqlalchemy.exc.IntegrityError: (psycopg2.errors.ForeignKeyViolation) insert or update on table "task_fail" violates foreign key constraint "task_fail_ti_fkey"
DETAIL:  Key (dag_id, task_id, run_id, map_index)=(pyspark_etl_dag, run_pyspark_etl, manual__2024-12-06T18:37:47.068773+00:00, -1) is not present in table "task_instance".

[SQL: INSERT INTO task_fail (task_id, dag_id, run_id, map_index, start_date, end_date, duration) VALUES (%(task_id)s, %(dag_id)s, %(run_id)s, %(map_index)s, %(start_date)s, %(end_date)s, %(duration)s) RETURNING task_fail.id]
[parameters: {'task_id': 'run_pyspark_etl', 'dag_id': 'pyspark_etl_dag', 'run_id': 'manual__2024-12-06T18:37:47.068773+00:00', 'map_index': -1, 'start_date': datetime.datetime(2024, 12, 6, 18, 37, 48, 265469, tzinfo=Timezone('UTC')), 'end_date': datetime.datetime(2024, 12, 6, 18, 39, 39, 542601, tzinfo=Timezone('UTC')), 'duration': 111}]
(Background on this error at: https://sqlalche.me/e/14/gkpj)
[2024-12-06T18:39:39.895+0000] {process_utils.py:80} INFO - Process psutil.Process(pid=320, status='terminated', exitcode=1, started='18:37:47') (320) terminated with exit code 1
[2024-12-06T18:39:43.389+0000] {standard_task_runner.py:217} INFO - Process not found (most likely exited), stop collecting metrics
[2024-12-06T18:40:39.522+0000] {process_utils.py:150} WARNING - process psutil.Process(pid=322, name='java', status='zombie', started='18:37:47') did not respond to SIGTERM. Trying SIGKILL
[2024-12-06T18:40:39.524+0000] {process_utils.py:87} INFO - Sending the signal 9 to group 320
[2024-12-06T18:41:39.562+0000] {process_utils.py:161} ERROR - Process psutil.Process(pid=322, name='java', status='zombie', started='18:37:47') (322) could not be killed. Giving up.
