[2024-12-06T18:37:12.054+0000] {local_task_job_runner.py:123} INFO - ::group::Pre task execution logs
[2024-12-06T18:37:12.084+0000] {taskinstance.py:2613} INFO - Dependencies all met for dep_context=non-requeueable deps ti=<TaskInstance: pyspark_etl_dag.run_pyspark_etl manual__2024-12-06T18:06:28.556095+00:00 [queued]>
[2024-12-06T18:37:12.092+0000] {taskinstance.py:2613} INFO - Dependencies all met for dep_context=requeueable deps ti=<TaskInstance: pyspark_etl_dag.run_pyspark_etl manual__2024-12-06T18:06:28.556095+00:00 [queued]>
[2024-12-06T18:37:12.093+0000] {taskinstance.py:2866} INFO - Starting attempt 3 of 1
[2024-12-06T18:37:12.104+0000] {taskinstance.py:2889} INFO - Executing <Task(SparkSubmitOperator): run_pyspark_etl> on 2024-12-06 18:06:28.556095+00:00
[2024-12-06T18:37:12.109+0000] {standard_task_runner.py:72} INFO - Started process 180 to run task
[2024-12-06T18:37:12.112+0000] {standard_task_runner.py:104} INFO - Running: ['***', 'tasks', 'run', 'pyspark_etl_dag', 'run_pyspark_etl', 'manual__2024-12-06T18:06:28.556095+00:00', '--job-id', '49', '--raw', '--subdir', 'DAGS_FOLDER/scripts_etl_dags.py', '--cfg-path', '/tmp/tmpiwd3hr8g']
[2024-12-06T18:37:12.115+0000] {standard_task_runner.py:105} INFO - Job 49: Subtask run_pyspark_etl
[2024-12-06T18:37:12.140+0000] {logging_mixin.py:190} WARNING - /home/***/.local/lib/python3.9/site-packages/***/settings.py:209 DeprecationWarning: The sql_alchemy_conn option in [core] has been moved to the sql_alchemy_conn option in [database] - the old setting has been used, but please update your config.
[2024-12-06T18:37:12.193+0000] {task_command.py:467} INFO - Running <TaskInstance: pyspark_etl_dag.run_pyspark_etl manual__2024-12-06T18:06:28.556095+00:00 [running]> on host 9a0780602dc6
[2024-12-06T18:37:12.297+0000] {taskinstance.py:3132} INFO - Exporting env vars: AIRFLOW_CTX_DAG_OWNER='***' AIRFLOW_CTX_DAG_ID='pyspark_etl_dag' AIRFLOW_CTX_TASK_ID='run_pyspark_etl' AIRFLOW_CTX_EXECUTION_DATE='2024-12-06T18:06:28.556095+00:00' AIRFLOW_CTX_TRY_NUMBER='3' AIRFLOW_CTX_DAG_RUN_ID='manual__2024-12-06T18:06:28.556095+00:00'
[2024-12-06T18:37:12.298+0000] {taskinstance.py:731} INFO - ::endgroup::
[2024-12-06T18:37:12.334+0000] {base.py:84} INFO - Retrieving connection 'spark_default'
[2024-12-06T18:37:12.335+0000] {spark_submit.py:473} INFO - Spark-Submit cmd: spark-submit --master yarn --conf spark.executor.memory=2g --conf spark.driver.memory=2g --name arrow-spark --queue root.default /opt/***/scripts/scripts_etl.py
[2024-12-06T18:37:15.439+0000] {spark_submit.py:634} INFO - 24/12/06 18:37:15 INFO SparkContext: Running Spark version 3.4.4
[2024-12-06T18:37:15.508+0000] {spark_submit.py:634} INFO - 24/12/06 18:37:15 WARN NativeCodeLoader: Unable to load native-hadoop library for your platform... using builtin-java classes where applicable
[2024-12-06T18:37:15.593+0000] {spark_submit.py:634} INFO - 24/12/06 18:37:15 INFO ResourceUtils: ==============================================================
[2024-12-06T18:37:15.594+0000] {spark_submit.py:634} INFO - 24/12/06 18:37:15 INFO ResourceUtils: No custom resources configured for spark.driver.
[2024-12-06T18:37:15.595+0000] {spark_submit.py:634} INFO - 24/12/06 18:37:15 INFO ResourceUtils: ==============================================================
[2024-12-06T18:37:15.596+0000] {spark_submit.py:634} INFO - 24/12/06 18:37:15 INFO SparkContext: Submitted application: PostgreSQL Integration
[2024-12-06T18:37:15.613+0000] {spark_submit.py:634} INFO - 24/12/06 18:37:15 INFO ResourceProfile: Default ResourceProfile created, executor resources: Map(cores -> name: cores, amount: 1, script: , vendor: , memory -> name: memory, amount: 2048, script: , vendor: , offHeap -> name: offHeap, amount: 0, script: , vendor: ), task resources: Map(cpus -> name: cpus, amount: 1.0)
[2024-12-06T18:37:15.624+0000] {spark_submit.py:634} INFO - 24/12/06 18:37:15 INFO ResourceProfile: Limiting resource is cpus at 1 tasks per executor
[2024-12-06T18:37:15.626+0000] {spark_submit.py:634} INFO - 24/12/06 18:37:15 INFO ResourceProfileManager: Added ResourceProfile id: 0
[2024-12-06T18:37:15.681+0000] {spark_submit.py:634} INFO - 24/12/06 18:37:15 INFO SecurityManager: Changing view acls to: ***
[2024-12-06T18:37:15.682+0000] {spark_submit.py:634} INFO - 24/12/06 18:37:15 INFO SecurityManager: Changing modify acls to: ***
[2024-12-06T18:37:15.683+0000] {spark_submit.py:634} INFO - 24/12/06 18:37:15 INFO SecurityManager: Changing view acls groups to:
[2024-12-06T18:37:15.684+0000] {spark_submit.py:634} INFO - 24/12/06 18:37:15 INFO SecurityManager: Changing modify acls groups to:
[2024-12-06T18:37:15.684+0000] {spark_submit.py:634} INFO - 24/12/06 18:37:15 INFO SecurityManager: SecurityManager: authentication disabled; ui acls disabled; users with view permissions: ***; groups with view permissions: EMPTY; users with modify permissions: ***; groups with modify permissions: EMPTY
[2024-12-06T18:37:15.904+0000] {spark_submit.py:634} INFO - 24/12/06 18:37:15 INFO Utils: Successfully started service 'sparkDriver' on port 41901.
[2024-12-06T18:37:15.945+0000] {spark_submit.py:634} INFO - 24/12/06 18:37:15 INFO SparkEnv: Registering MapOutputTracker
[2024-12-06T18:37:15.978+0000] {spark_submit.py:634} INFO - 24/12/06 18:37:15 INFO SparkEnv: Registering BlockManagerMaster
[2024-12-06T18:37:15.998+0000] {spark_submit.py:634} INFO - 24/12/06 18:37:15 INFO BlockManagerMasterEndpoint: Using org.apache.spark.storage.DefaultTopologyMapper for getting topology information
[2024-12-06T18:37:16.000+0000] {spark_submit.py:634} INFO - 24/12/06 18:37:15 INFO BlockManagerMasterEndpoint: BlockManagerMasterEndpoint up
[2024-12-06T18:37:16.024+0000] {spark_submit.py:634} INFO - 24/12/06 18:37:16 INFO SparkEnv: Registering BlockManagerMasterHeartbeat
[2024-12-06T18:37:16.044+0000] {spark_submit.py:634} INFO - 24/12/06 18:37:16 INFO DiskBlockManager: Created local directory at /tmp/blockmgr-3ca851c2-462c-436e-a5c9-c88f6b83c370
[2024-12-06T18:37:16.060+0000] {spark_submit.py:634} INFO - 24/12/06 18:37:16 INFO MemoryStore: MemoryStore started with capacity 1048.8 MiB
[2024-12-06T18:37:16.091+0000] {spark_submit.py:634} INFO - 24/12/06 18:37:16 INFO SparkEnv: Registering OutputCommitCoordinator
[2024-12-06T18:37:16.241+0000] {spark_submit.py:634} INFO - 24/12/06 18:37:16 INFO JettyUtils: Start Jetty 0.0.0.0:4040 for SparkUI
[2024-12-06T18:37:16.303+0000] {spark_submit.py:634} INFO - 24/12/06 18:37:16 INFO Utils: Successfully started service 'SparkUI' on port 4040.
[2024-12-06T18:37:16.341+0000] {spark_submit.py:634} INFO - 24/12/06 18:37:16 INFO SparkContext: Added JAR /opt/***/scripts/postgresql-42.7.4.jar at spark://9a0780602dc6:41901/jars/postgresql-42.7.4.jar with timestamp 1733510235424
[2024-12-06T18:37:16.488+0000] {spark_submit.py:634} INFO - 24/12/06 18:37:16 INFO DefaultNoHARMFailoverProxyProvider: Connecting to ResourceManager at /0.0.0.0:8032
[2024-12-06T18:37:17.665+0000] {spark_submit.py:634} INFO - 24/12/06 18:37:17 INFO Client: Retrying connect to server: 0.0.0.0/0.0.0.0:8032. Already tried 0 time(s); retry policy is RetryUpToMaximumCountWithFixedSleep(maxRetries=10, sleepTime=1000 MILLISECONDS)
[2024-12-06T18:37:18.667+0000] {spark_submit.py:634} INFO - 24/12/06 18:37:18 INFO Client: Retrying connect to server: 0.0.0.0/0.0.0.0:8032. Already tried 1 time(s); retry policy is RetryUpToMaximumCountWithFixedSleep(maxRetries=10, sleepTime=1000 MILLISECONDS)
[2024-12-06T18:37:19.668+0000] {spark_submit.py:634} INFO - 24/12/06 18:37:19 INFO Client: Retrying connect to server: 0.0.0.0/0.0.0.0:8032. Already tried 2 time(s); retry policy is RetryUpToMaximumCountWithFixedSleep(maxRetries=10, sleepTime=1000 MILLISECONDS)
[2024-12-06T18:37:20.670+0000] {spark_submit.py:634} INFO - 24/12/06 18:37:20 INFO Client: Retrying connect to server: 0.0.0.0/0.0.0.0:8032. Already tried 3 time(s); retry policy is RetryUpToMaximumCountWithFixedSleep(maxRetries=10, sleepTime=1000 MILLISECONDS)
[2024-12-06T18:37:21.671+0000] {spark_submit.py:634} INFO - 24/12/06 18:37:21 INFO Client: Retrying connect to server: 0.0.0.0/0.0.0.0:8032. Already tried 4 time(s); retry policy is RetryUpToMaximumCountWithFixedSleep(maxRetries=10, sleepTime=1000 MILLISECONDS)
[2024-12-06T18:37:22.672+0000] {spark_submit.py:634} INFO - 24/12/06 18:37:22 INFO Client: Retrying connect to server: 0.0.0.0/0.0.0.0:8032. Already tried 5 time(s); retry policy is RetryUpToMaximumCountWithFixedSleep(maxRetries=10, sleepTime=1000 MILLISECONDS)
[2024-12-06T18:37:23.673+0000] {spark_submit.py:634} INFO - 24/12/06 18:37:23 INFO Client: Retrying connect to server: 0.0.0.0/0.0.0.0:8032. Already tried 6 time(s); retry policy is RetryUpToMaximumCountWithFixedSleep(maxRetries=10, sleepTime=1000 MILLISECONDS)
[2024-12-06T18:37:24.674+0000] {spark_submit.py:634} INFO - 24/12/06 18:37:24 INFO Client: Retrying connect to server: 0.0.0.0/0.0.0.0:8032. Already tried 7 time(s); retry policy is RetryUpToMaximumCountWithFixedSleep(maxRetries=10, sleepTime=1000 MILLISECONDS)
[2024-12-06T18:37:25.675+0000] {spark_submit.py:634} INFO - 24/12/06 18:37:25 INFO Client: Retrying connect to server: 0.0.0.0/0.0.0.0:8032. Already tried 8 time(s); retry policy is RetryUpToMaximumCountWithFixedSleep(maxRetries=10, sleepTime=1000 MILLISECONDS)
[2024-12-06T18:37:26.676+0000] {spark_submit.py:634} INFO - 24/12/06 18:37:26 INFO Client: Retrying connect to server: 0.0.0.0/0.0.0.0:8032. Already tried 9 time(s); retry policy is RetryUpToMaximumCountWithFixedSleep(maxRetries=10, sleepTime=1000 MILLISECONDS)
[2024-12-06T18:37:27.682+0000] {spark_submit.py:634} INFO - 24/12/06 18:37:27 INFO Client: Retrying connect to server: 0.0.0.0/0.0.0.0:8032. Already tried 0 time(s); retry policy is RetryUpToMaximumCountWithFixedSleep(maxRetries=10, sleepTime=1000 MILLISECONDS)
[2024-12-06T18:37:28.684+0000] {spark_submit.py:634} INFO - 24/12/06 18:37:28 INFO Client: Retrying connect to server: 0.0.0.0/0.0.0.0:8032. Already tried 1 time(s); retry policy is RetryUpToMaximumCountWithFixedSleep(maxRetries=10, sleepTime=1000 MILLISECONDS)
[2024-12-06T18:37:29.685+0000] {spark_submit.py:634} INFO - 24/12/06 18:37:29 INFO Client: Retrying connect to server: 0.0.0.0/0.0.0.0:8032. Already tried 2 time(s); retry policy is RetryUpToMaximumCountWithFixedSleep(maxRetries=10, sleepTime=1000 MILLISECONDS)
[2024-12-06T18:37:30.684+0000] {spark_submit.py:634} INFO - 24/12/06 18:37:30 INFO Client: Retrying connect to server: 0.0.0.0/0.0.0.0:8032. Already tried 3 time(s); retry policy is RetryUpToMaximumCountWithFixedSleep(maxRetries=10, sleepTime=1000 MILLISECONDS)
[2024-12-06T18:37:31.685+0000] {spark_submit.py:634} INFO - 24/12/06 18:37:31 INFO Client: Retrying connect to server: 0.0.0.0/0.0.0.0:8032. Already tried 4 time(s); retry policy is RetryUpToMaximumCountWithFixedSleep(maxRetries=10, sleepTime=1000 MILLISECONDS)
[2024-12-06T18:37:32.686+0000] {spark_submit.py:634} INFO - 24/12/06 18:37:32 INFO Client: Retrying connect to server: 0.0.0.0/0.0.0.0:8032. Already tried 5 time(s); retry policy is RetryUpToMaximumCountWithFixedSleep(maxRetries=10, sleepTime=1000 MILLISECONDS)
[2024-12-06T18:37:33.687+0000] {spark_submit.py:634} INFO - 24/12/06 18:37:33 INFO Client: Retrying connect to server: 0.0.0.0/0.0.0.0:8032. Already tried 6 time(s); retry policy is RetryUpToMaximumCountWithFixedSleep(maxRetries=10, sleepTime=1000 MILLISECONDS)
[2024-12-06T18:37:34.687+0000] {spark_submit.py:634} INFO - 24/12/06 18:37:34 INFO Client: Retrying connect to server: 0.0.0.0/0.0.0.0:8032. Already tried 7 time(s); retry policy is RetryUpToMaximumCountWithFixedSleep(maxRetries=10, sleepTime=1000 MILLISECONDS)
[2024-12-06T18:37:35.688+0000] {spark_submit.py:634} INFO - 24/12/06 18:37:35 INFO Client: Retrying connect to server: 0.0.0.0/0.0.0.0:8032. Already tried 8 time(s); retry policy is RetryUpToMaximumCountWithFixedSleep(maxRetries=10, sleepTime=1000 MILLISECONDS)
[2024-12-06T18:37:36.689+0000] {spark_submit.py:634} INFO - 24/12/06 18:37:36 INFO Client: Retrying connect to server: 0.0.0.0/0.0.0.0:8032. Already tried 9 time(s); retry policy is RetryUpToMaximumCountWithFixedSleep(maxRetries=10, sleepTime=1000 MILLISECONDS)
[2024-12-06T18:37:36.690+0000] {spark_submit.py:634} INFO - 24/12/06 18:37:36 INFO RetryInvocationHandler: java.net.ConnectException: Your endpoint configuration is wrong; For more details see:  http://wiki.apache.org/hadoop/UnsetHostnameOrPort, while invoking ApplicationClientProtocolPBClientImpl.getNewApplication over null after 1 failover attempts. Trying to failover after sleeping for 36170ms.
[2024-12-06T18:38:13.861+0000] {spark_submit.py:634} INFO - 24/12/06 18:38:13 INFO Client: Retrying connect to server: 0.0.0.0/0.0.0.0:8032. Already tried 0 time(s); retry policy is RetryUpToMaximumCountWithFixedSleep(maxRetries=10, sleepTime=1000 MILLISECONDS)
[2024-12-06T18:38:14.863+0000] {spark_submit.py:634} INFO - 24/12/06 18:38:14 INFO Client: Retrying connect to server: 0.0.0.0/0.0.0.0:8032. Already tried 1 time(s); retry policy is RetryUpToMaximumCountWithFixedSleep(maxRetries=10, sleepTime=1000 MILLISECONDS)
[2024-12-06T18:38:15.863+0000] {spark_submit.py:634} INFO - 24/12/06 18:38:15 INFO Client: Retrying connect to server: 0.0.0.0/0.0.0.0:8032. Already tried 2 time(s); retry policy is RetryUpToMaximumCountWithFixedSleep(maxRetries=10, sleepTime=1000 MILLISECONDS)
[2024-12-06T18:38:16.864+0000] {spark_submit.py:634} INFO - 24/12/06 18:38:16 INFO Client: Retrying connect to server: 0.0.0.0/0.0.0.0:8032. Already tried 3 time(s); retry policy is RetryUpToMaximumCountWithFixedSleep(maxRetries=10, sleepTime=1000 MILLISECONDS)
[2024-12-06T18:38:17.865+0000] {spark_submit.py:634} INFO - 24/12/06 18:38:17 INFO Client: Retrying connect to server: 0.0.0.0/0.0.0.0:8032. Already tried 4 time(s); retry policy is RetryUpToMaximumCountWithFixedSleep(maxRetries=10, sleepTime=1000 MILLISECONDS)
[2024-12-06T18:38:18.867+0000] {spark_submit.py:634} INFO - 24/12/06 18:38:18 INFO Client: Retrying connect to server: 0.0.0.0/0.0.0.0:8032. Already tried 5 time(s); retry policy is RetryUpToMaximumCountWithFixedSleep(maxRetries=10, sleepTime=1000 MILLISECONDS)
[2024-12-06T18:38:19.870+0000] {spark_submit.py:634} INFO - 24/12/06 18:38:19 INFO Client: Retrying connect to server: 0.0.0.0/0.0.0.0:8032. Already tried 6 time(s); retry policy is RetryUpToMaximumCountWithFixedSleep(maxRetries=10, sleepTime=1000 MILLISECONDS)
[2024-12-06T18:38:20.871+0000] {spark_submit.py:634} INFO - 24/12/06 18:38:20 INFO Client: Retrying connect to server: 0.0.0.0/0.0.0.0:8032. Already tried 7 time(s); retry policy is RetryUpToMaximumCountWithFixedSleep(maxRetries=10, sleepTime=1000 MILLISECONDS)
[2024-12-06T18:38:21.874+0000] {spark_submit.py:634} INFO - 24/12/06 18:38:21 INFO Client: Retrying connect to server: 0.0.0.0/0.0.0.0:8032. Already tried 8 time(s); retry policy is RetryUpToMaximumCountWithFixedSleep(maxRetries=10, sleepTime=1000 MILLISECONDS)
[2024-12-06T18:38:22.875+0000] {spark_submit.py:634} INFO - 24/12/06 18:38:22 INFO Client: Retrying connect to server: 0.0.0.0/0.0.0.0:8032. Already tried 9 time(s); retry policy is RetryUpToMaximumCountWithFixedSleep(maxRetries=10, sleepTime=1000 MILLISECONDS)
[2024-12-06T18:38:22.878+0000] {spark_submit.py:634} INFO - 24/12/06 18:38:22 INFO RetryInvocationHandler: java.net.ConnectException: Your endpoint configuration is wrong; For more details see:  http://wiki.apache.org/hadoop/UnsetHostnameOrPort, while invoking ApplicationClientProtocolPBClientImpl.getNewApplication over null after 2 failover attempts. Trying to failover after sleeping for 23915ms.
[2024-12-06T18:38:47.795+0000] {spark_submit.py:634} INFO - 24/12/06 18:38:47 INFO Client: Retrying connect to server: 0.0.0.0/0.0.0.0:8032. Already tried 0 time(s); retry policy is RetryUpToMaximumCountWithFixedSleep(maxRetries=10, sleepTime=1000 MILLISECONDS)
[2024-12-06T18:38:48.796+0000] {spark_submit.py:634} INFO - 24/12/06 18:38:48 INFO Client: Retrying connect to server: 0.0.0.0/0.0.0.0:8032. Already tried 1 time(s); retry policy is RetryUpToMaximumCountWithFixedSleep(maxRetries=10, sleepTime=1000 MILLISECONDS)
[2024-12-06T18:38:49.798+0000] {spark_submit.py:634} INFO - 24/12/06 18:38:49 INFO Client: Retrying connect to server: 0.0.0.0/0.0.0.0:8032. Already tried 2 time(s); retry policy is RetryUpToMaximumCountWithFixedSleep(maxRetries=10, sleepTime=1000 MILLISECONDS)
[2024-12-06T18:38:50.800+0000] {spark_submit.py:634} INFO - 24/12/06 18:38:50 INFO Client: Retrying connect to server: 0.0.0.0/0.0.0.0:8032. Already tried 3 time(s); retry policy is RetryUpToMaximumCountWithFixedSleep(maxRetries=10, sleepTime=1000 MILLISECONDS)
[2024-12-06T18:38:51.801+0000] {spark_submit.py:634} INFO - 24/12/06 18:38:51 INFO Client: Retrying connect to server: 0.0.0.0/0.0.0.0:8032. Already tried 4 time(s); retry policy is RetryUpToMaximumCountWithFixedSleep(maxRetries=10, sleepTime=1000 MILLISECONDS)
[2024-12-06T18:38:52.803+0000] {spark_submit.py:634} INFO - 24/12/06 18:38:52 INFO Client: Retrying connect to server: 0.0.0.0/0.0.0.0:8032. Already tried 5 time(s); retry policy is RetryUpToMaximumCountWithFixedSleep(maxRetries=10, sleepTime=1000 MILLISECONDS)
[2024-12-06T18:38:53.804+0000] {spark_submit.py:634} INFO - 24/12/06 18:38:53 INFO Client: Retrying connect to server: 0.0.0.0/0.0.0.0:8032. Already tried 6 time(s); retry policy is RetryUpToMaximumCountWithFixedSleep(maxRetries=10, sleepTime=1000 MILLISECONDS)
[2024-12-06T18:38:54.805+0000] {spark_submit.py:634} INFO - 24/12/06 18:38:54 INFO Client: Retrying connect to server: 0.0.0.0/0.0.0.0:8032. Already tried 7 time(s); retry policy is RetryUpToMaximumCountWithFixedSleep(maxRetries=10, sleepTime=1000 MILLISECONDS)
[2024-12-06T18:38:55.807+0000] {spark_submit.py:634} INFO - 24/12/06 18:38:55 INFO Client: Retrying connect to server: 0.0.0.0/0.0.0.0:8032. Already tried 8 time(s); retry policy is RetryUpToMaximumCountWithFixedSleep(maxRetries=10, sleepTime=1000 MILLISECONDS)
[2024-12-06T18:38:56.809+0000] {spark_submit.py:634} INFO - 24/12/06 18:38:56 INFO Client: Retrying connect to server: 0.0.0.0/0.0.0.0:8032. Already tried 9 time(s); retry policy is RetryUpToMaximumCountWithFixedSleep(maxRetries=10, sleepTime=1000 MILLISECONDS)
[2024-12-06T18:38:56.811+0000] {spark_submit.py:634} INFO - 24/12/06 18:38:56 INFO RetryInvocationHandler: java.net.ConnectException: Your endpoint configuration is wrong; For more details see:  http://wiki.apache.org/hadoop/UnsetHostnameOrPort, while invoking ApplicationClientProtocolPBClientImpl.getNewApplication over null after 3 failover attempts. Trying to failover after sleeping for 43114ms.
[2024-12-06T18:39:33.745+0000] {local_task_job_runner.py:346} WARNING - State of this instance has been externally set to None. Terminating instance.
[2024-12-06T18:39:33.747+0000] {local_task_job_runner.py:245} INFO - ::endgroup::
[2024-12-06T18:39:33.748+0000] {process_utils.py:132} INFO - Sending 15 to group 180. PIDs of all processes in the group: [182, 239, 180]
[2024-12-06T18:39:33.750+0000] {process_utils.py:87} INFO - Sending the signal 15 to group 180
[2024-12-06T18:39:33.751+0000] {taskinstance.py:3093} ERROR - Received SIGTERM. Terminating subprocesses.
[2024-12-06T18:39:33.752+0000] {spark_submit.py:760} INFO - Sending kill signal to spark-submit
[2024-12-06T18:39:33.772+0000] {taskinstance.py:3311} ERROR - Task failed with exception
Traceback (most recent call last):
  File "/home/airflow/.local/lib/python3.9/site-packages/airflow/models/taskinstance.py", line 767, in _execute_task
    result = _execute_callable(context=context, **execute_callable_kwargs)
  File "/home/airflow/.local/lib/python3.9/site-packages/airflow/models/taskinstance.py", line 733, in _execute_callable
    return ExecutionCallableRunner(
  File "/home/airflow/.local/lib/python3.9/site-packages/airflow/utils/operator_helpers.py", line 252, in run
    return self.func(*args, **kwargs)
  File "/home/airflow/.local/lib/python3.9/site-packages/airflow/models/baseoperator.py", line 417, in wrapper
    return func(self, *args, **kwargs)
  File "/home/airflow/.local/lib/python3.9/site-packages/airflow/providers/apache/spark/operators/spark_submit.py", line 176, in execute
    self._hook.submit(self.application)
  File "/home/airflow/.local/lib/python3.9/site-packages/airflow/providers/apache/spark/hooks/spark_submit.py", line 548, in submit
    self._process_spark_submit_log(iter(self._submit_sp.stdout))  # type: ignore
  File "/home/airflow/.local/lib/python3.9/site-packages/airflow/providers/apache/spark/hooks/spark_submit.py", line 597, in _process_spark_submit_log
    for line in itr:
  File "/home/airflow/.local/lib/python3.9/site-packages/airflow/models/taskinstance.py", line 3095, in signal_handler
    raise AirflowTaskTerminated("Task received SIGTERM signal")
airflow.exceptions.AirflowTaskTerminated: Task received SIGTERM signal
[2024-12-06T18:39:33.778+0000] {taskinstance.py:1225} INFO - Marking task as FAILED. dag_id=pyspark_etl_dag, task_id=run_pyspark_etl, run_id=manual__2024-12-06T18:06:28.556095+00:00, execution_date=20241206T180628, start_date=20241206T183712, end_date=20241206T183933
[2024-12-06T18:39:33.792+0000] {taskinstance.py:340} INFO - ::group::Post task execution logs
[2024-12-06T18:39:33.793+0000] {standard_task_runner.py:124} ERROR - Failed to execute job 49 for task run_pyspark_etl ((psycopg2.errors.ForeignKeyViolation) insert or update on table "task_fail" violates foreign key constraint "task_fail_ti_fkey"
DETAIL:  Key (dag_id, task_id, run_id, map_index)=(pyspark_etl_dag, run_pyspark_etl, manual__2024-12-06T18:06:28.556095+00:00, -1) is not present in table "task_instance".

[SQL: INSERT INTO task_fail (task_id, dag_id, run_id, map_index, start_date, end_date, duration) VALUES (%(task_id)s, %(dag_id)s, %(run_id)s, %(map_index)s, %(start_date)s, %(end_date)s, %(duration)s) RETURNING task_fail.id]
[parameters: {'task_id': 'run_pyspark_etl', 'dag_id': 'pyspark_etl_dag', 'run_id': 'manual__2024-12-06T18:06:28.556095+00:00', 'map_index': -1, 'start_date': datetime.datetime(2024, 12, 6, 18, 37, 12, 85227, tzinfo=Timezone('UTC')), 'end_date': datetime.datetime(2024, 12, 6, 18, 39, 33, 777309, tzinfo=Timezone('UTC')), 'duration': 141}]
(Background on this error at: https://sqlalche.me/e/14/gkpj); 180)
Traceback (most recent call last):
  File "/home/airflow/.local/lib/python3.9/site-packages/airflow/models/taskinstance.py", line 273, in _run_raw_task
    TaskInstance._execute_task_with_callbacks(
  File "/home/airflow/.local/lib/python3.9/site-packages/airflow/models/taskinstance.py", line 3159, in _execute_task_with_callbacks
    result = self._execute_task(context, task_orig)
  File "/home/airflow/.local/lib/python3.9/site-packages/airflow/models/taskinstance.py", line 3183, in _execute_task
    return _execute_task(self, context, task_orig)
  File "/home/airflow/.local/lib/python3.9/site-packages/airflow/models/taskinstance.py", line 767, in _execute_task
    result = _execute_callable(context=context, **execute_callable_kwargs)
  File "/home/airflow/.local/lib/python3.9/site-packages/airflow/models/taskinstance.py", line 733, in _execute_callable
    return ExecutionCallableRunner(
  File "/home/airflow/.local/lib/python3.9/site-packages/airflow/utils/operator_helpers.py", line 252, in run
    return self.func(*args, **kwargs)
  File "/home/airflow/.local/lib/python3.9/site-packages/airflow/models/baseoperator.py", line 417, in wrapper
    return func(self, *args, **kwargs)
  File "/home/airflow/.local/lib/python3.9/site-packages/airflow/providers/apache/spark/operators/spark_submit.py", line 176, in execute
    self._hook.submit(self.application)
  File "/home/airflow/.local/lib/python3.9/site-packages/airflow/providers/apache/spark/hooks/spark_submit.py", line 548, in submit
    self._process_spark_submit_log(iter(self._submit_sp.stdout))  # type: ignore
  File "/home/airflow/.local/lib/python3.9/site-packages/airflow/providers/apache/spark/hooks/spark_submit.py", line 597, in _process_spark_submit_log
    for line in itr:
  File "/home/airflow/.local/lib/python3.9/site-packages/airflow/models/taskinstance.py", line 3095, in signal_handler
    raise AirflowTaskTerminated("Task received SIGTERM signal")
airflow.exceptions.AirflowTaskTerminated: Task received SIGTERM signal

During handling of the above exception, another exception occurred:

Traceback (most recent call last):
  File "/home/airflow/.local/lib/python3.9/site-packages/sqlalchemy/engine/base.py", line 1900, in _execute_context
    self.dialect.do_execute(
  File "/home/airflow/.local/lib/python3.9/site-packages/sqlalchemy/engine/default.py", line 736, in do_execute
    cursor.execute(statement, parameters)
psycopg2.errors.ForeignKeyViolation: insert or update on table "task_fail" violates foreign key constraint "task_fail_ti_fkey"
DETAIL:  Key (dag_id, task_id, run_id, map_index)=(pyspark_etl_dag, run_pyspark_etl, manual__2024-12-06T18:06:28.556095+00:00, -1) is not present in table "task_instance".


The above exception was the direct cause of the following exception:

Traceback (most recent call last):
  File "/home/airflow/.local/lib/python3.9/site-packages/airflow/task/task_runner/standard_task_runner.py", line 117, in _start_by_fork
    ret = args.func(args, dag=self.dag)
  File "/home/airflow/.local/lib/python3.9/site-packages/airflow/cli/cli_config.py", line 49, in command
    return func(*args, **kwargs)
  File "/home/airflow/.local/lib/python3.9/site-packages/airflow/utils/cli.py", line 116, in wrapper
    return f(*args, **kwargs)
  File "/home/airflow/.local/lib/python3.9/site-packages/airflow/cli/commands/task_command.py", line 483, in task_run
    task_return_code = _run_task_by_selected_method(args, _dag, ti)
  File "/home/airflow/.local/lib/python3.9/site-packages/airflow/cli/commands/task_command.py", line 256, in _run_task_by_selected_method
    return _run_raw_task(args, ti)
  File "/home/airflow/.local/lib/python3.9/site-packages/airflow/cli/commands/task_command.py", line 341, in _run_raw_task
    return ti._run_raw_task(
  File "/home/airflow/.local/lib/python3.9/site-packages/airflow/utils/session.py", line 97, in wrapper
    return func(*args, session=session, **kwargs)
  File "/home/airflow/.local/lib/python3.9/site-packages/airflow/models/taskinstance.py", line 3005, in _run_raw_task
    return _run_raw_task(
  File "/home/airflow/.local/lib/python3.9/site-packages/airflow/models/taskinstance.py", line 327, in _run_raw_task
    ti.handle_failure(e, test_mode, context, session=session)
  File "/home/airflow/.local/lib/python3.9/site-packages/airflow/utils/session.py", line 94, in wrapper
    return func(*args, **kwargs)
  File "/home/airflow/.local/lib/python3.9/site-packages/airflow/models/taskinstance.py", line 3428, in handle_failure
    _handle_failure(
  File "/home/airflow/.local/lib/python3.9/site-packages/airflow/utils/session.py", line 94, in wrapper
    return func(*args, **kwargs)
  File "/home/airflow/.local/lib/python3.9/site-packages/airflow/api_internal/internal_api_call.py", line 166, in wrapper
    return func(*args, **kwargs)
  File "/home/airflow/.local/lib/python3.9/site-packages/airflow/models/taskinstance.py", line 1243, in _handle_failure
    TaskInstance.save_to_db(failure_context["ti"], session)
  File "/home/airflow/.local/lib/python3.9/site-packages/airflow/api_internal/internal_api_call.py", line 166, in wrapper
    return func(*args, **kwargs)
  File "/home/airflow/.local/lib/python3.9/site-packages/airflow/utils/session.py", line 94, in wrapper
    return func(*args, **kwargs)
  File "/home/airflow/.local/lib/python3.9/site-packages/airflow/models/taskinstance.py", line 3400, in save_to_db
    session.flush()
  File "/home/airflow/.local/lib/python3.9/site-packages/sqlalchemy/orm/session.py", line 3444, in flush
    self._flush(objects)
  File "/home/airflow/.local/lib/python3.9/site-packages/sqlalchemy/orm/session.py", line 3584, in _flush
    transaction.rollback(_capture_exception=True)
  File "/home/airflow/.local/lib/python3.9/site-packages/sqlalchemy/util/langhelpers.py", line 70, in __exit__
    compat.raise_(
  File "/home/airflow/.local/lib/python3.9/site-packages/sqlalchemy/util/compat.py", line 210, in raise_
    raise exception
  File "/home/airflow/.local/lib/python3.9/site-packages/sqlalchemy/orm/session.py", line 3544, in _flush
    flush_context.execute()
  File "/home/airflow/.local/lib/python3.9/site-packages/sqlalchemy/orm/unitofwork.py", line 456, in execute
    rec.execute(self)
  File "/home/airflow/.local/lib/python3.9/site-packages/sqlalchemy/orm/unitofwork.py", line 630, in execute
    util.preloaded.orm_persistence.save_obj(
  File "/home/airflow/.local/lib/python3.9/site-packages/sqlalchemy/orm/persistence.py", line 245, in save_obj
    _emit_insert_statements(
  File "/home/airflow/.local/lib/python3.9/site-packages/sqlalchemy/orm/persistence.py", line 1238, in _emit_insert_statements
    result = connection._execute_20(
  File "/home/airflow/.local/lib/python3.9/site-packages/sqlalchemy/engine/base.py", line 1705, in _execute_20
    return meth(self, args_10style, kwargs_10style, execution_options)
  File "/home/airflow/.local/lib/python3.9/site-packages/sqlalchemy/sql/elements.py", line 334, in _execute_on_connection
    return connection._execute_clauseelement(
  File "/home/airflow/.local/lib/python3.9/site-packages/sqlalchemy/engine/base.py", line 1572, in _execute_clauseelement
    ret = self._execute_context(
  File "/home/airflow/.local/lib/python3.9/site-packages/sqlalchemy/engine/base.py", line 1943, in _execute_context
    self._handle_dbapi_exception(
  File "/home/airflow/.local/lib/python3.9/site-packages/sqlalchemy/engine/base.py", line 2124, in _handle_dbapi_exception
    util.raise_(
  File "/home/airflow/.local/lib/python3.9/site-packages/sqlalchemy/util/compat.py", line 210, in raise_
    raise exception
  File "/home/airflow/.local/lib/python3.9/site-packages/sqlalchemy/engine/base.py", line 1900, in _execute_context
    self.dialect.do_execute(
  File "/home/airflow/.local/lib/python3.9/site-packages/sqlalchemy/engine/default.py", line 736, in do_execute
    cursor.execute(statement, parameters)
sqlalchemy.exc.IntegrityError: (psycopg2.errors.ForeignKeyViolation) insert or update on table "task_fail" violates foreign key constraint "task_fail_ti_fkey"
DETAIL:  Key (dag_id, task_id, run_id, map_index)=(pyspark_etl_dag, run_pyspark_etl, manual__2024-12-06T18:06:28.556095+00:00, -1) is not present in table "task_instance".

[SQL: INSERT INTO task_fail (task_id, dag_id, run_id, map_index, start_date, end_date, duration) VALUES (%(task_id)s, %(dag_id)s, %(run_id)s, %(map_index)s, %(start_date)s, %(end_date)s, %(duration)s) RETURNING task_fail.id]
[parameters: {'task_id': 'run_pyspark_etl', 'dag_id': 'pyspark_etl_dag', 'run_id': 'manual__2024-12-06T18:06:28.556095+00:00', 'map_index': -1, 'start_date': datetime.datetime(2024, 12, 6, 18, 37, 12, 85227, tzinfo=Timezone('UTC')), 'end_date': datetime.datetime(2024, 12, 6, 18, 39, 33, 777309, tzinfo=Timezone('UTC')), 'duration': 141}]
(Background on this error at: https://sqlalche.me/e/14/gkpj)
[2024-12-06T18:39:33.843+0000] {process_utils.py:80} INFO - Process psutil.Process(pid=180, status='terminated', exitcode=1, started='18:37:11') (180) terminated with exit code 1
[2024-12-06T18:39:37.251+0000] {standard_task_runner.py:217} INFO - Process not found (most likely exited), stop collecting metrics
[2024-12-06T18:40:33.781+0000] {process_utils.py:150} WARNING - process psutil.Process(pid=239, name='python', status='zombie', started='18:37:14') did not respond to SIGTERM. Trying SIGKILL
[2024-12-06T18:40:33.783+0000] {process_utils.py:150} WARNING - process psutil.Process(pid=182, name='java', status='zombie', started='18:37:11') did not respond to SIGTERM. Trying SIGKILL
[2024-12-06T18:40:33.786+0000] {process_utils.py:87} INFO - Sending the signal 9 to group 180
[2024-12-06T18:41:33.809+0000] {process_utils.py:161} ERROR - Process psutil.Process(pid=239, name='python', status='zombie', started='18:37:14') (239) could not be killed. Giving up.
[2024-12-06T18:41:33.811+0000] {process_utils.py:161} ERROR - Process psutil.Process(pid=182, name='java', status='zombie', started='18:37:11') (182) could not be killed. Giving up.
